profiling/test_data.json
{"orders": [{"id": 892510, "side": "sell", "price": "98.81", "quantity": 75}, {"id": 7739561, "side": "buy", "price": "100.37", "quantity": 54}, {"id": 6545716, "side": "sell", "price": "107.20", "quantity": 48}, {"id": 4388785, "side": "buy", "price": "104.00", "quantity": 55}, {"id": 4330153, "side": "buy", "price": "97.25", "quantity": 85}, {"id": 8585980, "side": "buy", "price": "104.53", "quantity": 2}, {"id": 859457, "side": "buy", "price": "100.08", "quantity": 11}, {"id": 6973681, "side": "buy", "price": "94.47", "quantity": 48}, {"id": 2014696, "side": "sell", "price": "90.43", "quantity": 59}, {"id": 941774, "side": "sell", "price": "90.07", "quantity": 18}, {"id": 5264790, "side": "buy", "price": "94.48", "quantity": 61}, {"id": 9756224, "side": "sell", "price": "106.38", "quantity": 3}, {"id": 7357524, "side": "sell", "price": "99.27", "quantity": 25}, {"id": 7611398, "side": "sell", "price": "99.03", "quantity": 46}, {"id": 7174773, "side": "sell", "price": "97.98", "quantity": 5}, {"id": 7860644, "side": "buy", "price": "95.12", "quantity": 64}, {"id": 5132266, "side": "buy", "price": "104.30", "quantity": 54}, {"id": 1281137, "side": "sell", "price": "90.25", "quantity": 57}, {"id": 8397483, "side": "sell", "price": "102.24", "quantity": 52}, {"id": 4503860, "side": "sell", "price": "108.74", "quantity": 70}, {"id": 5003520, "side": "buy", "price": "107.61", "quantity": 66}, {"id": 3707981, "side": "sell", "price": "97.38", "quantity": 67}, {"id": 1825497, "side": "buy", "price": "107.10", "quantity": 22}, {"id": 9267650, "side": "sell", "price": "94.75", "quantity": 69}, {"id": 7815675, "side": "buy", "price": "94.82", "quantity": 18}, {"id": 6438652, "side": "buy", "price": "96.87", "quantity": 3}, {"id": 4024144, "side": "sell", "price": "90.35", "quantity": 98}, {"id": 8227617, "side": "sell", "price": "95.31", "quantity": 18}, {"id": 5454292, "side": "buy", "price": "107.09", "quantity": 12}, {"id": 4434142, "side": "buy", "price": "105.25", "quantity": 31}, {"id": 4504596, "side": "buy", "price": "96.58", "quantity": 100}, {"id": 2272388, "side": "buy", "price": "96.25", "quantity": 87}, {"id": 921360, "side": "sell", "price": "96.94", "quantity": 72}, {"id": 5545848, "side": "buy", "price": "92.38", "quantity": 19}, {"id": 8878899, "side": "buy", "price": "93.16", "quantity": 63}, {"id": 638173, "side": "sell", "price": "109.86", "quantity": 84}, {"id": 8582913, "side": "sell", "price": "103.86", "quantity": 34}, {"id": 8276312, "side": "buy", "price": "103.55", "quantity": 26}, {"id": 2767597, "side": "sell", "price": "95.60", "quantity": 87}, {"id": 6316644, "side": "sell", "price": "107.12", "quantity": 14}, {"id": 1652291, "side": "sell", "price": "93.53", "quantity": 92}, {"id": 7580878, "side": "buy", "price": "109.38", "quantity": 48}, {"id": 7005230, "side": "sell", "price": "100.07", "quantity": 73}, {"id": 3545260, "side": "sell", "price": "96.61", "quantity": 38}, {"id": 679201, "side": "sell", "price": "105.01", "quantity": 71}, {"id": 9706981, "side": "sell", "price": "98.34", "quantity": 93}, {"id": 4456875, "side": "buy", "price": "95.39", "quantity": 50}, {"id": 8931212, "side": "sell", "price": "103.67", "quantity": 22}, {"id": 6779191, "side": "sell", "price": "104.44", "quantity": 8}, {"id": 7783835, "side": "sell", "price": "102.07", "quantity": 93}, {"id": 7598995, "side": "sell", "price": "99.24", "quantity": 100}, {"id": 1946388, "side": "buy", "price": "96.57", "quantity": 66}, {"id": 3639061, "side": "sell", "price": "98.07", "quantity": 2}, {"id": 4667211, "side": "sell", "price": "107.49", "quantity": 89}, {"id": 4977916, "side": "sell", "price": "97.19", "quantity": 50}, {"id": 438038, "side": "sell", "price": "109.35", "quantity": 24}, {"id": 5465696, "side": "sell", "price": "92.91", "quantity": 37}, {"id": 1542895, "side": "buy", "price": "93.25", "quantity": 95}, {"id": 7433760, "side": "sell", "price": "96.65", "quantity": 78}, {"id": 6830490, "side": "sell", "price": "90.05", "quantity": 60}, {"id": 9225279, "side": "buy", "price": "107.59", "quantity": 74}, {"id": 7447622, "side": "buy", "price": "96.81", "quantity": 85}, {"id": 3666427, "side": "buy", "price": "92.04", "quantity": 63}, {"id": 9675098, "side": "buy", "price": "102.37", "quantity": 32}, {"id": 4108504, "side": "sell", "price": "109.17", "quantity": 8}, {"id": 3258254, "side": "buy", "price": "109.88", "quantity": 13}, {"id": 9055358, "side": "sell", "price": "92.15", "quantity": 24}, {"id": 3704598, "side": "buy", "price": "105.86", "quantity": 77}, {"id": 763432, "side": "buy", "price": "97.24", "quantity": 10}, {"id": 4695559, "side": "sell", "price": "106.73", "quantity": 13}, {"id": 7956800, "side": "buy", "price": "102.13", "quantity": 98}, {"id": 1894714, "side": "sell", "price": "104.64", "quantity": 41}, {"id": 4629406, "side": "sell", "price": "106.76", "quantity": 13}, {"id": 1299216, "side": "buy", "price": "107.91", "quantity": 88}, {"id": 6864783, "side": "buy", "price": "92.87", "quantity": 97}, {"id": 4757050, "side": "sell", "price": "104.48", "quantity": 51}, {"id": 3301964, "side": "sell", "price": "92.82", "quantity": 12}, {"id": 2269094, "side": "buy", "price": "108.88", "quantity": 63}, {"id": 5644999, "side": "sell", "price": "102.57", "quantity": 87}, {"id": 6698140, "side": "buy", "price": "93.85", "quantity": 97}, {"id": 9403061, "side": "buy", "price": "95.85", "quantity": 58}, {"id": 4371520, "side": "sell", "price": "107.92", "quantity": 95}, {"id": 1606882, "side": "buy", "price": "102.89", "quantity": 84}, {"id": 8326782, "side": "buy", "price": "94.58", "quantity": 17}, {"id": 6297644, "side": "sell", "price": "106.41", "quantity": 64}, {"id": 7002652, "side": "sell", "price": "104.37", "quantity": 67}, {"id": 972267, "side": "buy", "price": "91.53", "quantity": 77}, {"id": 3123667, "side": "sell", "price": "95.66", "quantity": 54}, {"id": 7678440, "side": "sell", "price": "106.89", "quantity": 74}, {"id": 8322599, "side": "buy", "price": "97.02", "quantity": 59}, {"id": 4352167, "side": "buy", "price": "90.75", "quantity": 27}, {"id": 8047644, "side": "sell", "price": "102.08", "quantity": 49}, {"id": 8416919, "side": "buy", "price": "107.98", "quantity": 94}, {"id": 3874784, "side": "sell", "price": "101.13", "quantity": 85}, {"id": 8980877, "side": "buy", "price": "109.52", "quantity": 65}, {"id": 2883282, "side": "sell", "price": "92.28", "quantity": 33}, {"id": 2395578, "side": "sell", "price": "103.35", "quantity": 21}, {"id": 6824956, "side": "buy", "price": "103.00", "quantity": 29}, {"id": 6367619, "side": "sell", "price": "109.69", "quantity": 31}, {"id": 1397525, "side": "sell", "price": "100.42", "quantity": 97}, {"id": 8327368, "side": "sell", "price": "106.44", "quantity": 54}, {"id": 1999083, "side": "buy", "price": "92.90", "quantity": 40}, {"id": 8048992, "side": "buy", "price": "90.88", "quantity": 89}, {"id": 73623, "side": "sell", "price": "104.33", "quantity": 37}, {"id": 7968426, "side": "sell", "price": "90.07", "quantity": 80}, {"id": 7869244, "side": "buy", "price": "107.50", "quantity": 65}, {"id": 7803644, "side": "buy", "price": "90.41", "quantity": 31}, {"id": 6648509, "side": "buy", "price": "103.77", "quantity": 97}, {"id": 4715672, "side": "sell", "price": "99.04", "quantity": 69}, {"id": 7051654, "side": "sell", "price": "102.91", "quantity": 99}, {"id": 2771217, "side": "sell", "price": "102.47", "quantity": 1}, {"id": 7807291, "side": "buy", "price": "98.89", "quantity": 29}, {"id": 5556470, "side": "buy", "price": "99.63", "quantity": 34}, {"id": 4589158, "side": "buy", "price": "100.07", "quantity": 68}, {"id": 5056063, "side": "sell", "price": "103.54", "quantity": 84}, {"id": 5687412, "side": "buy", "price": "104.21", "quantity": 13}, {"id": 372624, "side": "buy", "price": "98.99", "quantity": 16}, {"id": 1397970, "side": "buy", "price": "97.05", "quantity": 68}, {"id": 2454812, "side": "buy", "price": "90.85", "quantity": 36}, {"id": 1145301, "side": "sell"
